<?xml version="1.0"?>
	<robot name="rur">
	     <link name="base_footprint">
	     </link>
            <joint name="base_joint" type="fixed">
                <parent link="base_footprint"/>
                <child link="base_link"/>
                <origin xyz="0.0 0.0 0.010" rpy="0 0 0"/>
            </joint>
              
		<link name="base_link">
		</link>
		
	<!--	<link name="laser">
		</link>

		<joint name="base_link_to_laser" type="fixed">                                 
			<parent link="base_link"/>
			<child link="laser"/>
			<origin xyz="0 0 0.75" rpy="0.0 0.0 3.141592"/>
			<axis xyz="0 0 0"/>
		</joint>
		-->
	    <link name="imu_link"/>	
            <joint name="imu_joint" type="fixed">
                <parent link="base_link"/>
                <child link="imu_link"/>
                <origin xyz="-0.2 0 0" rpy="0 0 0"/>
            </joint>

 
    <!--    <link name="base_scan">
        </link>
            <joint name="scan_joint" type="fixed">
                <parent link="base_link"/>
                <child link="base_scan"/>
                <origin xyz="0 0 0.75" rpy="0 0 3.14159265359"/>
            </joint>

-->

<!--for wheels-->

<link name="wheel_left_link">
    </link>
    <joint name="wheel_0_joint" type="continuous">
        <parent link="base_link"/>
        <child link="wheel_left_link"/>
        <origin xyz="0 1 0" rpy="0 0 1.57"/>
        <axis xyz="0 0 1"/>
    </joint>



<link name="wheel_right_link">
  </link>
    <joint name="wheel_1_joint" type="continuous">
        <parent link="base_link"/>
        <child link="wheel_right_link"/>
        <origin xyz="1.0 0 0" rpy="0 0 -1.57"/>
        <axis xyz="0 0 1"/>
    </joint>



	</robot>
